<mujoco model="juggling_platform_2d">
  <option cone="elliptic" timestep="3e-3" integrator="implicitfast"/>
  <compiler angle="radian" coordinate="local" meshdir="/home/admin/workspace/src/descriptions/balancing_platform_2d_description/meshes"/>
  <option gravity="0 0 -9.81"/>
  
  <default>
    <joint damping="0.0"/>
    <pair solref="0.05 0.03" solimp="0.001 0.005 4 0.5 0.001"/>
    <geom type="mesh" contype="1" conaffinity="1" rgba="0.9 0.9 0.9 1"/>
  </default>

  <statistic center="0.0 0 0.2" extent="1.0"/>

  <visual>
    <headlight diffuse="0.6 0.6 0.6" ambient="0.3 0.3 0.3" specular="0 0 0"/>
    <rgba haze="0.15 0.25 0.35 1"/>
    <global azimuth="90" elevation="-20"/>
  </visual>

  <asset>
    <mesh name="motor" file="motor.stl" scale="0.001 0.001 0.001"/>
    <mesh name="arm" file="arm.stl" scale="0.001 0.001 0.001"/>
    <mesh name="platform" file="platform.stl" scale="0.001 0.001 0.001"/>

    <texture type="skybox" builtin="gradient" rgb1="0.3 0.5 0.7" rgb2="0 0 0" width="512" height="3072"/>
    <texture type="2d" name="groundplane" builtin="checker" mark="edge" rgb1="0.2 0.3 0.4" rgb2="0.1 0.2 0.3"
             markrgb="0.8 0.8 0.8" width="300" height="300"/>
    <material name="groundplane" texture="groundplane" texuniform="true" texrepeat="5 5" reflectance="0.2"/>
  </asset>

  <worldbody>
    <light pos="0 0 1.5" dir="0 0 -1" directional="true"/>
    <geom name="floor" size="0.5 0.5 0.05" type="plane" material="groundplane"/>
    <body name="left_motor" pos="-0.14 0 0">
      <geom mesh="motor"/>
      <inertial pos="0 0 0.004761" mass="23.468"
        diaginertia="1.031498 1.057814 1.273548"/>

      <body name="left_low_arm" pos="0 0 0.014">
        <joint name="left_motor_joint" type="hinge" axis="0 1 0"
               range="-1.5 0.0" limited="true"/>
        <geom mesh="arm" pos="0 0 0.04"/>
        <inertial pos="0 0 -0.003129" mass="0.107464"
          diaginertia="0.000052495 0.00004983497 0.000004385676"/>

        <body name="left_top_arm" pos="0 0 0.08">
          <joint name="left_arm_joint" type="hinge" axis="0 1 0"
                 range="0.75 2.5"/>
          <geom mesh="arm" pos="0 0 0.04"/>
          <inertial pos="0 0 -0.003129" mass="0.107464"
            diaginertia="0.000052495 0.00004983497 0.000004385676"/>
          
          <body name="platform" pos="0 0 0.08" euler="0 0 1.5708">
            <joint name="left_platform_joint" type="hinge" axis="1 0 0"
                   range="-1 0.2" damping="0.1"/>
            <geom mesh="platform" pos="0 -0.14 -0.005" contype="0" conaffinity="0"/>
            <geom name="platform_collision" type="box" size="0.1 0.1 0.005" pos="0 -0.14 0" rgba="1 1 1 1" friction="5.2 0.0 0.0"/>
            <inertial pos="0.0 0.0 0.004974" mass="0.4891"
              diaginertia="0.002571 0.002504 0.005067"/>

            <body name="right_top_arm" pos="0 -0.28 0" euler="0 0 1.5708">
              <joint name="right_platform_joint" type="hinge" axis="0 1 0"
                    range="-0.2 1" damping="0.1"/>
              <geom mesh="arm" pos="0 0 -0.04"/>
              <inertial pos="0 0 -0.003129" mass="0.4891"
                diaginertia="0.000052495 0.00004983497 0.000004385676"/>

              <body name="right_low_arm" pos="0 0 -0.08" euler="0 0 0">
                <joint name="right_arm_joint" type="hinge" axis="0 1 0"
                      range="-2.5 -0.75"/>
                <geom mesh="arm" pos="0 0 -0.04"/>
                <inertial pos="0 0 -0.003129" mass="0.4891"
                  diaginertia="0.000052495 0.00004983497 0.000004385676"/>

                <body name="right_motor" pos="0 0 -0.08" euler="0 0 3.141592654">
                  <joint name="right_motor_joint" type="hinge" axis="0 1 0"
                      range="-1.5 0.0" limited="true"/>
                  <geom mesh="motor" pos="0 0 -0.014"/>
                  <inertial pos="0 0 0.004761" mass="23.468"
                    diaginertia="1.031498 1.057814 1.273548"/>
                </body>
              </body>
            </body>
          </body>
        </body>
      </body>
    </body>

    <body name="ball" pos="0 0 0" euler="0 0 0">
      <!-- <freejoint name="ball_joint"/> -->
      <joint name="ball_joint_x" type="slide" axis="1 0 0"/>
      <joint name="ball_joint_z" type="slide" axis="0 0 1"/>
      <!-- <inertial pos="0 0 0" mass="0.0027" diaginertia="4.3e-7 4.3e-7 4.3e-7"/> -->
      <inertial pos="0 0 0" mass="0.027" diaginertia="4.3e-6 4.3e-6 4.3e-6"/>
      <geom name="ball" type="sphere" size="0.02" rgba="1 0.729 0 1" friction="0.2 0.0 0.0"/>
    </body>
    <!-- <site name="debug_anchor_1" pos="-0.14 0 0" size="0.02" rgba="1 0 0 1"/>
    <site name="debug_anchor_2" pos="0.14 0 0" size="0.02" rgba="0 0 1 1"/>  -->
  </worldbody>

  <equality>
    <connect name="fix_left_motor"  active="true" body1="world" body2="left_motor"  anchor="-0.14 0 0" solref="0.02 1"/>
    <connect name="fix_right_motor" active="true" body1="world" body2="right_motor" anchor="0 0.14 0" solref="0.02 1"/>
  </equality>

  <contact>
    <exclude body1="left_motor" body2="ball"/>
    <exclude body1="right_motor" body2="ball"/>
    <exclude body1="left_low_arm" body2="ball"/>
    <exclude body1="left_top_arm" body2="ball"/>
    <exclude body1="right_low_arm" body2="ball"/>
    <exclude body1="right_top_arm" body2="ball"/>
    <exclude body1="platform" body2="left_motor"/>
    <exclude body1="platform" body2="right_motor"/>
    <exclude body1="platform" body2="left_low_arm"/>
    <exclude body1="platform" body2="left_top_arm"/>
    <exclude body1="platform" body2="right_low_arm"/>
    <exclude body1="platform" body2="right_top_arm"/>
    <exclude body1="left_low_arm" body2="left_top_arm"/>
    <exclude body1="left_low_arm" body2="left_motor"/>
    <exclude body1="right_low_arm" body2="right_top_arm"/>
    <exclude body1="right_low_arm" body2="right_motor"/>
    <pair geom1="platform_collision" geom2="ball"/>
    <pair geom1="floor" geom2="ball"/>
  </contact>

  <actuator>
    <position name="left_motor" joint="left_motor_joint" kp="10" kv="0.5" ctrlrange="-1.57 0.0"/>
    <position name="right_motor" joint="right_motor_joint" kp="10" kv="0.5" ctrlrange="-1.57 0.0"/>
  </actuator>

  <keyframe>
    <key name="home" qpos="-1.047197551 2.094395102 -1.047197551 1.047197551 -2.094395102 -1.047197551 0.0 0.3"
     ctrl="-1.047197551 -1.047197551"/>
  </keyframe>

</mujoco>
